Workbook

Sheet Table des types
C1: Type offensif (capacité)
C2: Acier | D2: Combat | E2: Dragon | F2: Eau | G2: Électrik | H2: Fée | I2: Feu | J2: Glace | K2: Insecte | L2: Normal | M2: Plante | N2: Poison | O2: Psy | P2: Roche | Q2: Sol | R2: Spectre | S2: Ténèbres | T2: Vol
A3: Type défensif (Pokémon) | B3: Acier | C3: ×½ | D3: ×2 | E3: ×½ | F3: ×1 | G3: ×1 | H3: ×½ | I3: ×2 | J3: ×½ | K3: ×½ | L3: ×½ | M3: ×½ | N3: ×0 | O3: ×½ | P3: ×½ | Q3: ×2 | R3: ×1 | S3: ×1 | T3: ×½
B4: Combat | C4: ×1 | D4: ×1 | E4: ×1 | F4: ×1 | G4: ×1 | H4: ×2 | I4: ×1 | J4: ×1 | K4: ×½ | L4: ×1 | M4: ×1 | N4: ×1 | O4: ×2 | P4: ×½ | Q4: ×1 | R4: ×1 | S4: ×½ | T4: ×2
B5: Dragon | C5: ×1 | D5: ×1 | E5: ×2 | F5: ×½ | G5: ×½ | H5: ×2 | I5: ×½ | J5: ×2 | K5: ×1 | L5: ×1 | M5: ×½ | N5: ×1 | O5: ×1 | P5: ×1 | Q5: ×1 | R5: ×1 | S5: ×1 | T5: ×1
B6: Eau | C6: ×½ | D6: ×1 | E6: ×1 | F6: ×½ | G6: ×2 | H6: ×1 | I6: ×½ | J6: ×½ | K6: ×1 | L6: ×1 | M6: ×2 | N6: ×1 | O6: ×1 | P6: ×1 | Q6: ×1 | R6: ×1 | S6: ×1 | T6: ×1
B7: Électrik | C7: ×½ | D7: ×1 | E7: ×1 | F7: ×1 | G7: ×½ | H7: ×1 | I7: ×1 | J7: ×1 | K7: ×1 | L7: ×1 | M7: ×1 | N7: ×1 | O7: ×1 | P7: ×1 | Q7: ×2 | R7: ×1 | S7: ×1 | T7: ×½
B8: Fée | C8: ×2 | D8: ×½ | E8: ×0 | F8: ×1 | G8: ×1 | H8: ×1 | I8: ×1 | J8: ×1 | K8: ×½ | L8: ×1 | M8: ×1 | N8: ×2 | O8: ×1 | P8: ×1 | Q8: ×1 | R8: ×1 | S8: ×½ | T8: ×1
B9: Feu | C9: ×½ | D9: ×1 | E9: ×1 | F9: ×2 | G9: ×1 | H9: ×½ | I9: ×½ | J9: ×½ | K9: ×½ | L9: ×1 | M9: ×½ | N9: ×1 | O9: ×1 | P9: ×2 | Q9: ×2 | R9: ×1 | S9: ×1 | T9: ×1
B10: Glace | C10: ×2 | D10: ×2 | E10: ×1 | F10: ×1 | G10: ×1 | H10: ×1 | I10: ×2 | J10: ×½ | K10: ×1 | L10: ×1 | M10: ×1 | N10: ×1 | O10: ×1 | P10: ×2 | Q10: ×1 | R10: ×1 | S10: ×1 | T10: ×1
B11: Insecte | C11: ×1 | D11: ×½ | E11: ×1 | F11: ×1 | G11: ×1 | H11: ×1 | I11: ×2 | J11: ×1 | K11: ×1 | L11: ×1 | M11: ×½ | N11: ×1 | O11: ×1 | P11: ×2 | Q11: ×½ | R11: ×1 | S11: ×1 | T11: ×2
B12: Normal | C12: ×1 | D12: ×2 | E12: ×1 | F12: ×1 | G12: ×1 | H12: ×1 | I12: ×1 | J12: ×1 | K12: ×1 | L12: ×1 | M12: ×1 | N12: ×1 | O12: ×1 | P12: ×1 | Q12: ×1 | R12: ×0 | S12: ×1 | T12: ×1
B13: Plante | C13: ×1 | D13: ×1 | E13: ×1 | F13: ×½ | G13: ×½ | H13: ×1 | I13: ×2 | J13: ×2 | K13: ×2 | L13: ×1 | M13: ×½ | N13: ×2 | O13: ×1 | P13: ×1 | Q13: ×½ | R13: ×1 | S13: ×1 | T13: ×2
B14: Poison | C14: ×1 | D14: ×½ | E14: ×1 | F14: ×1 | G14: ×1 | H14: ×½ | I14: ×1 | J14: ×1 | K14: ×½ | L14: ×1 | M14: ×½ | N14: ×½ | O14: ×2 | P14: ×1 | Q14: ×2 | R14: ×1 | S14: ×1 | T14: ×1
B15: Psy | C15: ×1 | D15: ×½ | E15: ×1 | F15: ×1 | G15: ×1 | H15: ×1 | I15: ×1 | J15: ×1 | K15: ×2 | L15: ×1 | M15: ×1 | N15: ×1 | O15: ×½ | P15: ×1 | Q15: ×1 | R15: ×2 | S15: ×2 | T15: ×1
... B20: Vol | C20: ×1 | D20: ×½ | E20: ×1 | F20: ×1 | G20: ×2 | H20: ×1 | I20: ×1 | J20: ×2 | K20: ×½ | L20: ×1 | M20: ×½ | N20: ×1 | O20: ×1 | P20: ×2 | Q20: ×0 | R20: ×1 | S20: ×1 | T20: ×1
A22: Lecture : une capacité du type de la colonne frappe un Pokémon du type de la ligne avec le multiplicateur de la case. Un Pokémon à deux types cumule les deux multiplicateurs (×2 et ×2 donnent ×4).
A23: Source : gTypeEffectivenessTable (src/data/types_info.h), B_UPDATED_TYPE_MATCHUPS = GEN_LATEST (include/config/battle.h), règles de la 6e génération et suivantes. Extrait le 14/10/2026.

Sheet Combats (hors revanche)
A1: Starter | B1: Tous | D1: Choisissez votre starter : les combats de rival des deux autres se grisent. Ctrl+Alt+L (Données > Réappliquer) les masque.
H2: Affiché
A3: Ville Griotte | H3: Oui
A4: Nom | B4: Rival (si vous avez choisi GERMIGNON) | H4: =IF(OR($B$1="Tous",$B$1="GERMIGNON"),"Oui","Non")
A5: Pokémon | B5: HERICENDRE | H5: =IF(OR($B$1="Tous",$B$1="GERMIGNON"),"Oui","Non")
A6: Niveau | B6: 5 | H6: =IF(OR($B$1="Tous",$B$1="GERMIGNON"),"Oui","Non")
A7: Objet | B7: Aucun | H7: =IF(OR($B$1="Tous",$B$1="GERMIGNON"),"Oui","Non")
A8: Talent | B8: Brasier | H8: =IF(OR($B$1="Tous",$B$1="GERMIGNON"),"Oui","Non")
A9: Capacités | B9: Charge | H9: =IF(OR($B$1="Tous",$B$1="GERMIGNON"),"Oui","Non")
B10: Groz'Yeux | H10: =IF(OR($B$1="Tous",$B$1="GERMIGNON"),"Oui","Non")
H11: =IF(OR($B$1="Tous",$B$1="GERMIGNON"),"Oui","Non")
H12: =IF(OR($B$1="Tous",$B$1="GERMIGNON"),"Oui","Non")
A13: Nom | B13: Rival (si vous avez choisi HERICENDRE) | H13: =IF(OR($B$1="Tous",$B$1="HERICENDRE"),"Oui","Non")
A14: Pokémon | B14: KAIMINUS | H14: =IF(OR($B$1="Tous",$B$1="HERICENDRE"),"Oui","Non")
A15: Niveau | B15: 5 | H15: =IF(OR($B$1="Tous",$B$1="HERICENDRE"),"Oui","Non")
A16: Objet | B16: Aucun | H16: =IF(OR($B$1="Tous",$B$1="HERICENDRE"),"Oui","Non")
A17: Talent | B17: Torrent | H17: =IF(OR($B$1="Tous",$B$1="HERICENDRE"),"Oui","Non")
A18: Capacités | B18: Griffe | H18: =IF(OR($B$1="Tous",$B$1="HERICENDRE"),"Oui","Non")
B19: Groz'Yeux | H19: =IF(OR($B$1="Tous",$B$1="HERICENDRE"),"Oui","Non")
H20: =IF(OR($B$1="Tous",$B$1="HERICENDRE"),"Oui","Non")
H21: =IF(OR($B$1="Tous",$B$1="HERICENDRE"),"Oui","Non")
A22: Nom | B22: Rival (si vous avez choisi KAIMINUS) | H22: =IF(OR($B$1="Tous",$B$1="KAIMINUS"),"Oui","Non")
A23: Pokémon | B23: GERMIGNON | H23: =IF(OR($B$1="Tous",$B$1="KAIMINUS"),"Oui","Non")
A24: Niveau | B24: 5 | H24: =IF(OR($B$1="Tous",$B$1="KAIMINUS"),"Oui","Non")
A25: Objet | B25: Aucun | H25: =IF(OR($B$1="Tous",$B$1="KAIMINUS"),"Oui","Non")
A26: Talent | B26: Engrais | H26: =IF(OR($B$1="Tous",$B$1="KAIMINUS"),"Oui","Non")
A27: Capacités | B27: Charge | H27: =IF(OR($B$1="Tous",$B$1="KAIMINUS"),"Oui","Non")
B28: Rugissement | H28: =IF(OR($B$1="Tous",$B$1="KAIMINUS"),"Oui","Non")
H29: =IF(OR($B$1="Tous",$B$1="KAIMINUS"),"Oui","Non")
H30: =IF(OR($B$1="Tous",$B$1="KAIMINUS"),"Oui","Non")
A31: Route 30 | H31: Oui
A32: Nom | B32: Gamin Farouk | H32: Oui
A33: Pokémon | B33: RATTATA | H33: Oui
A34: Niveau | B34: 4 | H34: Oui
A35: Objet | B35: Aucun | H35: Oui
A36: Talent | B36: Fuite | H36: Oui
A37: Capacités | B37: Charge | H37: Oui
B38: Mimi-Queue | H38: Oui
B39: Vive-Attaque | H39: Oui
H40: Oui
...

Sheet Rencontres sauvages
A1: Zone | B1: Carte | C1: Moment | D1: Méthode | E1: Espèce | F1: Taux | G1: Niv. min | H1: Niv. max | I1: Disponible | J1: Lignée
A2: Acajou | B2: Mahoganytown_hns | C2: Toute la journée | D2: Éclate-Roc | E2: CAPUMAIN | F2: 0.9 | G2: 15 | H2: 15 | I2: =IF(OR(COUNTIF('Suivi des rencontres'!$A:$A,$A2)>0,COUNTIF('Suivi des rencontres'!$C:$C,$J2)>0),"Non","Oui") | J2: CAPUMAIN
A3: Acajou | B3: Mahoganytown_hns | C3: Toute la journée | D3: Éclate-Roc | E3: POMDEPIK | F3: 0.05 | G3: 15 | H3: 15 | I3: =IF(OR(COUNTIF('Suivi des rencontres'!$A:$A,$A3)>0,COUNTIF('Suivi des rencontres'!$C:$C,$J3)>0),"Non","Oui") | J3: POMDEPIK
A4: Acajou | B4: Mahoganytown_hns | C4: Toute la journée | D4: Éclate-Roc | E4: SCARHINO | F4: 0.05 | G4: 15 | H4: 15 | I4: =IF(OR(COUNTIF('Suivi des rencontres'!$A:$A,$A4)>0,COUNTIF('Suivi des rencontres'!$C:$C,$J4)>0),"Non","Oui") | J4: SCARHINO
A5: Akala | B5: AkalaIsle_hns | C5: Toute la journée | D5: Herbe | E5: MAGMAR | F5: 0.2 | G5: 43 | H5: 45 | I5: =IF(OR(COUNTIF('Suivi des rencontres'!$A:$A,$A5)>0,COUNTIF('Suivi des rencontres'!$C:$C,$J5)>0),"Non","Oui") | J5: MAGBY
A6: Akala | B6: AkalaIsle_hns | C6: Toute la journée | D6: Herbe | E6: TOUDOUDOU | F6: 0.2 | G6: 43 | H6: 45 | I6: =IF(OR(COUNTIF('Suivi des rencontres'!$A:$A,$A6)>0,COUNTIF('Suivi des rencontres'!$C:$C,$J6)>0),"Non","Oui") | J6: TOUDOUDOU
A7: Akala | B7: AkalaIsle_hns | C7: Toute la journée | D7: Herbe | E7: GOELISE | F7: 0.15 | G7: 43 | H7: 45 | I7: =IF(OR(COUNTIF('Suivi des rencontres'!$A:$A,$A7)>0,COUNTIF('Suivi des rencontres'!$C:$C,$J7)>0),"Non","Oui") | J7: GOELISE
A8: Akala | B8: AkalaIsle_hns | C8: Toute la journée | D8: Herbe | E8: CAPUMAIN | F8: 0.1 | G8: 43 | H8: 45 | I8: =IF(OR(COUNTIF('Suivi des rencontres'!$A:$A,$A8)>0,COUNTIF('Suivi des rencontres'!$C:$C,$J8)>0),"Non","Oui") | J8: CAPUMAIN
A9: Akala | B9: AkalaIsle_hns | C9: Toute la journée | D9: Herbe | E9: MAGBY | F9: 0.1 | G9: 43 | H9: 45 | I9: =IF(OR(COUNTIF('Suivi des rencontres'!$A:$A,$A9)>0,COUNTIF('Suivi des rencontres'!$C:$C,$J9)>0),"Non","Oui") | J9: MAGBY
A10: Akala | B10: AkalaIsle_hns | C10: Toute la journée | D10: Herbe | E10: NATU | F10: 0.1 | G10: 43 | H10: 45 | I10: =IF(OR(COUNTIF('Suivi des rencontres'!$A:$A,$A10)>0,COUNTIF('Suivi des rencontres'!$C:$C,$J10)>0),"Non","Oui") | J10: NATU
A11: Akala | B11: AkalaIsle_hns | C11: Toute la journée | D11: Herbe | E11: OSSELAIT | F11: 0.09 | G11: 43 | H11: 45 | I11: =IF(OR(COUNTIF('Suivi des rencontres'!$A:$A,$A11)>0,COUNTIF('Suivi des rencontres'!$C:$C,$J11)>0),"Non","Oui") | J11: OSSELAIT
A12: Akala | B12: AkalaIsle_hns | C12: Toute la journée | D12: Herbe | E12: TARINOR | F12: 0.04 | G12: 43 | H12: 45 | I12: =IF(OR(COUNTIF('Suivi des rencontres'!$A:$A,$A12)>0,COUNTIF('Suivi des rencontres'!$C:$C,$J12)>0),"Non","Oui") | J12: TARINOR
A13: Akala | B13: AkalaIsle_hns | C13: Toute la journée | D13: Herbe | E13: MAGANON | F13: 0.01 | G13: 43 | H13: 45 | I13: =IF(OR(COUNTIF('Suivi des rencontres'!$A:$A,$A13)>0,COUNTIF('Suivi des rencontres'!$C:$C,$J13)>0),"Non","Oui") | J13: MAGBY
... A3105: Ville Griotte | B3105: CherrygroveCity_hns | C3105: Nuit | D3105: Super Canne | E3105: KRABBOSS | F3105: 0.15 | G3105: 40 | H3105: 40 | I3105: =IF(OR(COUNTIF('Suivi des rencontres'!$A:$A,$A3105)>0,COUNTIF('Suivi des rencontres'!$C:$C,$J3105)>0),"Non","Oui") | J3105: KRABBY

Sheet Suivi des rencontres
A1: Zone | B1: Espèce | C1: Lignée | E1: Une ligne par rencontre : choisissez la zone puis l'espèce. Pour ajouter une ligne, tapez sous la dernière, ou Tab dans sa dernière cellule. Dans « Rencontres sauvages », les zones saisies et les lignées des espèces saisies se grisent aussitôt ; Ctrl+Alt+L (Données > Réappliquer) les masque.
C2: =IF($B2="","",IFERROR(VLOOKUP($B2,Listes!$A:$B,2,FALSE),"?"))

Sheet Listes
A1: Espèce | B1: Lignée | D1: Zone
A2: ABO | B2: ABO | D2: Acajou
A3: ABOMASNOW | B3: ABOMASNOW | D3: Akala
A4: ABRA | B4: ABRA | D4: Antre du Dragon
A5: ABSOL | B5: ABSOL | D5: Antre Noir
A6: AERODACTYL | B6: AERODACTYL | D6: Aquaria
A7: AEROMITE | B7: MIMITOSS | D7: Argenta
A8: AEROPTERYX | B8: ARKEAPTI | D8: Azuria
A9: AFLAMANOIR | B9: AFLAMANOIR | D9: Bois aux Chênes
A10: AGGRON | B10: AGGRON | D10: Bourg Geon
A11: AIRMURE | B11: AIRMURE | D11: Bourg Palette
A12: AKWAKWAK | B12: PSYKOKWAK | D12: Carmin sur Mer
... A120: CABLIFERE | B120: CABLIFERE | D120: Zone de Combat
A121: CABRIOLAINE | B121: CABRIOLAINE
A122: CACNEA | B122: CACNEA
A123: CACTURNE | B123: CACNEA
A124: CADOIZO | B124: CADOIZO
A125: CALYREX | B125: CALYREX
A126: CAMERUPT | B126: CHAMALLOT
A127: CANARBELLO | B127: COIFFETON
A128: CANARTICHO | B128: CANARTICHO
A129: CANARTICHO-G | B129: CANARTICHO-G
A130: CANCRELOVE | B130: CANCRELOVE
A131: CANDINE | B131: CROQUINE
A132: CANINOS | B132: CANINOS
... A1173: ZYGARDE | B1173: ZYGARDE
